<mujoco model="xpkg_urdf_archer_v1_0">
  <compiler angle="radian"/>

  <asset>
    <mesh name="base_link" content_type="model/stl" file="base_link.STL"/>
    <mesh name="link_1" content_type="model/stl" file="link_1.STL"/>
    <mesh name="link_2" content_type="model/stl" file="link_2.STL"/>
    <mesh name="link_3" content_type="model/stl" file="link_3.STL"/>
    <mesh name="link_4" content_type="model/stl" file="link_4.STL"/>
    <mesh name="link_5" content_type="model/stl" file="link_5.STL"/>
    <mesh name="link_6" content_type="model/stl" file="link_6.STL"/>
  </asset>

  <worldbody>
    <body name="base_link">
      <inertial pos="-0.001 0.0318 0" quat="0.5 0.5 0.5 0.5" mass="0.687" diaginertia="0.0007 0.0006 0.0005"/>
      <joint name="base_footprint_joint" pos="0 0 0" axis="0 0 1" range="-2.61 3.14" actuatorfrcrange="-6 6"/>
      <geom type="mesh" rgba="1 1 1 1" mesh="base_link"/>
      <body name="link_1" pos="0 0 0.0665">
        <inertial pos="0.008 0.0878 0.0023" mass="0.2154" diaginertia="0.0003 0.0003 0.0002"/>
        <joint name="joint_1" pos="0 0 0" axis="0 0 1" range="-2.61 3.14" actuatorfrcrange="-6 6"/>
        <geom type="mesh" rgba="1 1 1 1" mesh="link_1"/>
        <body name="link_2" pos="0.02 0 0.045">
          <inertial pos="0.0201 0.2429 0.0038" quat="0.705084 0.709124 0 0" mass="1.3123" diaginertia="0.0185 0.0182006 0.000699429"/>
          <joint name="joint_2" pos="0 0 0" axis="0 1 0" range="-1.57 2.09" actuatorfrcrange="-6 6"/>
          <geom type="mesh" rgba="1 1 1 1" mesh="link_2"/>
          <body name="link_3" pos="0 0 0.264">
            <inertial pos="-0.031 0.52 -0.0009" quat="0.681878 0.727918 0.0361167 0.0622413" mass="1.1083" diaginertia="0.0114986 0.0111374 0.001364"/>
            <joint name="joint_3" pos="0 0 0" axis="0 1 0" range="0 3.14" actuatorfrcrange="-6 6"/>
            <geom type="mesh" rgba="1 1 1 1" mesh="link_3"/>
            <body name="link_4" pos="-0.06 0 0.245">
              <inertial pos="-0.0998 0.6777 0.001" quat="0.653281 0.653281 0.270598 0.270598" mass="0.5398" diaginertia="0.0011 0.001 0.0005"/>
              <joint name="joint_4" pos="0 0 0" axis="0 1 0" range="-1.57 1.57" actuatorfrcrange="-6 6"/>
              <geom type="mesh" rgba="1 1 1 1" mesh="link_4"/>
              <body name="link_5" pos="-0.0553006 0 0.07025">
                <inertial pos="-0.0442 0.6936 -0.0001" quat="0.5 0.5 -0.5 0.5" mass="0.3984" diaginertia="0.0003 0.0002 0.0002"/>
                <joint name="joint_5" pos="0 0 0" axis="-1 0 0" range="-1.57 1.57" actuatorfrcrange="-6 6"/>
                <geom type="mesh" rgba="1 1 1 1" mesh="link_5"/>
                <body name="link_6" pos="0.0578 0 0.02895">
                  <inertial pos="-0.0389 0.7785 -0.0001" quat="0.707107 0.707107 0 0" mass="0.667" diaginertia="0.0015 0.001 0.0008"/>
                  <joint name="joint_6" pos="0 0 0" axis="0 0 1" range="-2.96 2.96" actuatorfrcrange="-6 6"/>
                  <geom type="mesh" rgba="1 1 1 1" mesh="link_6"/>
                </body>
              </body>
            </body>
          </body>
        </body>
      </body>
    </body>
  </worldbody>
</mujoco>
